{
 "cells": [
  {
   "cell_type": "code",
   "execution_count": 1,
   "metadata": {},
   "outputs": [
    {
     "ename": "ImportError",
     "evalue": "\n\nIMPORTANT: PLEASE READ THIS FOR ADVICE ON HOW TO SOLVE THIS ISSUE!\n\nImporting the numpy c-extensions failed.\n- Try uninstalling and reinstalling numpy.\n- If you have already done that, then:\n  1. Check that you expected to use Python3.7 from \"/Users/andrewgaitskell/Software/anaconda3/envs/env_voila/bin/python\",\n     and that you have no directories in your PATH or PYTHONPATH that can\n     interfere with the Python and numpy version \"1.18.1\" you're trying to use.\n  2. If (1) looks fine, you can open a new issue at\n     https://github.com/numpy/numpy/issues.  Please include details on:\n     - how you installed Python\n     - how you installed numpy\n     - your operating system\n     - whether or not you have multiple versions of Python installed\n     - if you built from source, your compiler versions and ideally a build log\n\n- If you're working with a numpy git repository, try `git clean -xdf`\n  (removes all files not under version control) and rebuild numpy.\n\nNote: this error has many possible causes, so please don't comment on\nan existing issue about this - open a new one instead.\n\nOriginal error was: dlopen(/Users/andrewgaitskell/Software/anaconda3/envs/env_voila/lib/python3.7/site-packages/numpy/core/_multiarray_umath.cpython-37m-darwin.so, 2): Library not loaded: @rpath/libopenblas.dylib\n  Referenced from: /Users/andrewgaitskell/Software/anaconda3/envs/env_voila/lib/python3.7/site-packages/numpy/core/_multiarray_umath.cpython-37m-darwin.so\n  Reason: image not found\n",
     "output_type": "error",
     "traceback": [
      "\u001b[0;31m---------------------------------------------------------------------------\u001b[0m",
      "\u001b[0;31mImportError\u001b[0m                               Traceback (most recent call last)",
      "\u001b[0;32m~/Software/anaconda3/envs/env_voila/lib/python3.7/site-packages/numpy/core/__init__.py\u001b[0m in \u001b[0;36m<module>\u001b[0;34m\u001b[0m\n\u001b[1;32m     23\u001b[0m \u001b[0;32mtry\u001b[0m\u001b[0;34m:\u001b[0m\u001b[0;34m\u001b[0m\u001b[0;34m\u001b[0m\u001b[0m\n\u001b[0;32m---> 24\u001b[0;31m     \u001b[0;32mfrom\u001b[0m \u001b[0;34m.\u001b[0m \u001b[0;32mimport\u001b[0m \u001b[0mmultiarray\u001b[0m\u001b[0;34m\u001b[0m\u001b[0;34m\u001b[0m\u001b[0m\n\u001b[0m\u001b[1;32m     25\u001b[0m \u001b[0;32mexcept\u001b[0m \u001b[0mImportError\u001b[0m \u001b[0;32mas\u001b[0m \u001b[0mexc\u001b[0m\u001b[0;34m:\u001b[0m\u001b[0;34m\u001b[0m\u001b[0;34m\u001b[0m\u001b[0m\n",
      "\u001b[0;32m~/Software/anaconda3/envs/env_voila/lib/python3.7/site-packages/numpy/core/multiarray.py\u001b[0m in \u001b[0;36m<module>\u001b[0;34m\u001b[0m\n\u001b[1;32m     13\u001b[0m \u001b[0;34m\u001b[0m\u001b[0m\n\u001b[0;32m---> 14\u001b[0;31m \u001b[0;32mfrom\u001b[0m \u001b[0;34m.\u001b[0m \u001b[0;32mimport\u001b[0m \u001b[0moverrides\u001b[0m\u001b[0;34m\u001b[0m\u001b[0;34m\u001b[0m\u001b[0m\n\u001b[0m\u001b[1;32m     15\u001b[0m \u001b[0;32mfrom\u001b[0m \u001b[0;34m.\u001b[0m \u001b[0;32mimport\u001b[0m \u001b[0m_multiarray_umath\u001b[0m\u001b[0;34m\u001b[0m\u001b[0;34m\u001b[0m\u001b[0m\n",
      "\u001b[0;32m~/Software/anaconda3/envs/env_voila/lib/python3.7/site-packages/numpy/core/overrides.py\u001b[0m in \u001b[0;36m<module>\u001b[0;34m\u001b[0m\n\u001b[1;32m      6\u001b[0m \u001b[0;34m\u001b[0m\u001b[0m\n\u001b[0;32m----> 7\u001b[0;31m from numpy.core._multiarray_umath import (\n\u001b[0m\u001b[1;32m      8\u001b[0m     add_docstring, implement_array_function, _get_implementing_args)\n",
      "\u001b[0;31mImportError\u001b[0m: dlopen(/Users/andrewgaitskell/Software/anaconda3/envs/env_voila/lib/python3.7/site-packages/numpy/core/_multiarray_umath.cpython-37m-darwin.so, 2): Library not loaded: @rpath/libopenblas.dylib\n  Referenced from: /Users/andrewgaitskell/Software/anaconda3/envs/env_voila/lib/python3.7/site-packages/numpy/core/_multiarray_umath.cpython-37m-darwin.so\n  Reason: image not found",
      "\nDuring handling of the above exception, another exception occurred:\n",
      "\u001b[0;31mImportError\u001b[0m                               Traceback (most recent call last)",
      "\u001b[0;32m<ipython-input-1-d8af561bf88a>\u001b[0m in \u001b[0;36m<module>\u001b[0;34m\u001b[0m\n\u001b[0;32m----> 1\u001b[0;31m \u001b[0;32mimport\u001b[0m \u001b[0mgeopandas\u001b[0m\u001b[0;34m\u001b[0m\u001b[0;34m\u001b[0m\u001b[0m\n\u001b[0m\u001b[1;32m      2\u001b[0m \u001b[0;32mimport\u001b[0m \u001b[0mgeoplot\u001b[0m\u001b[0;34m\u001b[0m\u001b[0;34m\u001b[0m\u001b[0m\n\u001b[1;32m      3\u001b[0m \u001b[0;34m\u001b[0m\u001b[0m\n\u001b[1;32m      4\u001b[0m world = geopandas.read_file(\n\u001b[1;32m      5\u001b[0m     \u001b[0mgeopandas\u001b[0m\u001b[0;34m.\u001b[0m\u001b[0mdatasets\u001b[0m\u001b[0;34m.\u001b[0m\u001b[0mget_path\u001b[0m\u001b[0;34m(\u001b[0m\u001b[0;34m'naturalearth_lowres'\u001b[0m\u001b[0;34m)\u001b[0m\u001b[0;34m\u001b[0m\u001b[0;34m\u001b[0m\u001b[0m\n",
      "\u001b[0;32m~/Software/anaconda3/envs/env_voila/lib/python3.7/site-packages/geopandas/__init__.py\u001b[0m in \u001b[0;36m<module>\u001b[0;34m\u001b[0m\n\u001b[0;32m----> 1\u001b[0;31m \u001b[0;32mfrom\u001b[0m \u001b[0mgeopandas\u001b[0m\u001b[0;34m.\u001b[0m\u001b[0mgeoseries\u001b[0m \u001b[0;32mimport\u001b[0m \u001b[0mGeoSeries\u001b[0m  \u001b[0;31m# noqa\u001b[0m\u001b[0;34m\u001b[0m\u001b[0;34m\u001b[0m\u001b[0m\n\u001b[0m\u001b[1;32m      2\u001b[0m \u001b[0;32mfrom\u001b[0m \u001b[0mgeopandas\u001b[0m\u001b[0;34m.\u001b[0m\u001b[0mgeodataframe\u001b[0m \u001b[0;32mimport\u001b[0m \u001b[0mGeoDataFrame\u001b[0m  \u001b[0;31m# noqa\u001b[0m\u001b[0;34m\u001b[0m\u001b[0;34m\u001b[0m\u001b[0m\n\u001b[1;32m      3\u001b[0m \u001b[0;32mfrom\u001b[0m \u001b[0mgeopandas\u001b[0m\u001b[0;34m.\u001b[0m\u001b[0marray\u001b[0m \u001b[0;32mimport\u001b[0m \u001b[0m_points_from_xy\u001b[0m \u001b[0;32mas\u001b[0m \u001b[0mpoints_from_xy\u001b[0m  \u001b[0;31m# noqa\u001b[0m\u001b[0;34m\u001b[0m\u001b[0;34m\u001b[0m\u001b[0m\n\u001b[1;32m      4\u001b[0m \u001b[0;34m\u001b[0m\u001b[0m\n\u001b[1;32m      5\u001b[0m \u001b[0;32mfrom\u001b[0m \u001b[0mgeopandas\u001b[0m\u001b[0;34m.\u001b[0m\u001b[0mio\u001b[0m\u001b[0;34m.\u001b[0m\u001b[0mfile\u001b[0m \u001b[0;32mimport\u001b[0m \u001b[0mread_file\u001b[0m  \u001b[0;31m# noqa\u001b[0m\u001b[0;34m\u001b[0m\u001b[0;34m\u001b[0m\u001b[0m\n",
      "\u001b[0;32m~/Software/anaconda3/envs/env_voila/lib/python3.7/site-packages/geopandas/geoseries.py\u001b[0m in \u001b[0;36m<module>\u001b[0;34m\u001b[0m\n\u001b[1;32m      2\u001b[0m \u001b[0;32mimport\u001b[0m \u001b[0mwarnings\u001b[0m\u001b[0;34m\u001b[0m\u001b[0;34m\u001b[0m\u001b[0m\n\u001b[1;32m      3\u001b[0m \u001b[0;34m\u001b[0m\u001b[0m\n\u001b[0;32m----> 4\u001b[0;31m \u001b[0;32mimport\u001b[0m \u001b[0mnumpy\u001b[0m \u001b[0;32mas\u001b[0m \u001b[0mnp\u001b[0m\u001b[0;34m\u001b[0m\u001b[0;34m\u001b[0m\u001b[0m\n\u001b[0m\u001b[1;32m      5\u001b[0m \u001b[0;32mimport\u001b[0m \u001b[0mpandas\u001b[0m \u001b[0;32mas\u001b[0m \u001b[0mpd\u001b[0m\u001b[0;34m\u001b[0m\u001b[0;34m\u001b[0m\u001b[0m\n\u001b[1;32m      6\u001b[0m \u001b[0;32mfrom\u001b[0m \u001b[0mpandas\u001b[0m \u001b[0;32mimport\u001b[0m \u001b[0mSeries\u001b[0m\u001b[0;34m\u001b[0m\u001b[0;34m\u001b[0m\u001b[0m\n",
      "\u001b[0;32m~/Software/anaconda3/envs/env_voila/lib/python3.7/site-packages/numpy/__init__.py\u001b[0m in \u001b[0;36m<module>\u001b[0;34m\u001b[0m\n\u001b[1;32m    140\u001b[0m     \u001b[0;32mfrom\u001b[0m \u001b[0;34m.\u001b[0m \u001b[0;32mimport\u001b[0m \u001b[0m_distributor_init\u001b[0m\u001b[0;34m\u001b[0m\u001b[0;34m\u001b[0m\u001b[0m\n\u001b[1;32m    141\u001b[0m \u001b[0;34m\u001b[0m\u001b[0m\n\u001b[0;32m--> 142\u001b[0;31m     \u001b[0;32mfrom\u001b[0m \u001b[0;34m.\u001b[0m \u001b[0;32mimport\u001b[0m \u001b[0mcore\u001b[0m\u001b[0;34m\u001b[0m\u001b[0;34m\u001b[0m\u001b[0m\n\u001b[0m\u001b[1;32m    143\u001b[0m     \u001b[0;32mfrom\u001b[0m \u001b[0;34m.\u001b[0m\u001b[0mcore\u001b[0m \u001b[0;32mimport\u001b[0m \u001b[0;34m*\u001b[0m\u001b[0;34m\u001b[0m\u001b[0;34m\u001b[0m\u001b[0m\n\u001b[1;32m    144\u001b[0m     \u001b[0;32mfrom\u001b[0m \u001b[0;34m.\u001b[0m \u001b[0;32mimport\u001b[0m \u001b[0mcompat\u001b[0m\u001b[0;34m\u001b[0m\u001b[0;34m\u001b[0m\u001b[0m\n",
      "\u001b[0;32m~/Software/anaconda3/envs/env_voila/lib/python3.7/site-packages/numpy/core/__init__.py\u001b[0m in \u001b[0;36m<module>\u001b[0;34m\u001b[0m\n\u001b[1;32m     52\u001b[0m \"\"\" % (sys.version_info[0], sys.version_info[1], sys.executable,\n\u001b[1;32m     53\u001b[0m         __version__, exc)\n\u001b[0;32m---> 54\u001b[0;31m     \u001b[0;32mraise\u001b[0m \u001b[0mImportError\u001b[0m\u001b[0;34m(\u001b[0m\u001b[0mmsg\u001b[0m\u001b[0;34m)\u001b[0m\u001b[0;34m\u001b[0m\u001b[0;34m\u001b[0m\u001b[0m\n\u001b[0m\u001b[1;32m     55\u001b[0m \u001b[0;32mfinally\u001b[0m\u001b[0;34m:\u001b[0m\u001b[0;34m\u001b[0m\u001b[0;34m\u001b[0m\u001b[0m\n\u001b[1;32m     56\u001b[0m     \u001b[0;32mfor\u001b[0m \u001b[0menvkey\u001b[0m \u001b[0;32min\u001b[0m \u001b[0menv_added\u001b[0m\u001b[0;34m:\u001b[0m\u001b[0;34m\u001b[0m\u001b[0;34m\u001b[0m\u001b[0m\n",
      "\u001b[0;31mImportError\u001b[0m: \n\nIMPORTANT: PLEASE READ THIS FOR ADVICE ON HOW TO SOLVE THIS ISSUE!\n\nImporting the numpy c-extensions failed.\n- Try uninstalling and reinstalling numpy.\n- If you have already done that, then:\n  1. Check that you expected to use Python3.7 from \"/Users/andrewgaitskell/Software/anaconda3/envs/env_voila/bin/python\",\n     and that you have no directories in your PATH or PYTHONPATH that can\n     interfere with the Python and numpy version \"1.18.1\" you're trying to use.\n  2. If (1) looks fine, you can open a new issue at\n     https://github.com/numpy/numpy/issues.  Please include details on:\n     - how you installed Python\n     - how you installed numpy\n     - your operating system\n     - whether or not you have multiple versions of Python installed\n     - if you built from source, your compiler versions and ideally a build log\n\n- If you're working with a numpy git repository, try `git clean -xdf`\n  (removes all files not under version control) and rebuild numpy.\n\nNote: this error has many possible causes, so please don't comment on\nan existing issue about this - open a new one instead.\n\nOriginal error was: dlopen(/Users/andrewgaitskell/Software/anaconda3/envs/env_voila/lib/python3.7/site-packages/numpy/core/_multiarray_umath.cpython-37m-darwin.so, 2): Library not loaded: @rpath/libopenblas.dylib\n  Referenced from: /Users/andrewgaitskell/Software/anaconda3/envs/env_voila/lib/python3.7/site-packages/numpy/core/_multiarray_umath.cpython-37m-darwin.so\n  Reason: image not found\n"
     ]
    }
   ],
   "source": [
    "import geopandas\n",
    "import geoplot\n",
    "\n",
    "world = geopandas.read_file(\n",
    "    geopandas.datasets.get_path('naturalearth_lowres')\n",
    ")\n",
    "boroughs = geopandas.read_file(\n",
    "    geoplot.datasets.get_path('nyc_boroughs')\n",
    ")\n",
    "collisions = geopandas.read_file(\n",
    "    geoplot.datasets.get_path('nyc_injurious_collisions')\n",
    ")\n"
   ]
  },
  {
   "cell_type": "code",
   "execution_count": null,
   "metadata": {},
   "outputs": [],
   "source": []
  }
 ],
 "metadata": {
  "kernelspec": {
   "display_name": "Python 3",
   "language": "python",
   "name": "python3"
  },
  "language_info": {
   "codemirror_mode": {
    "name": "ipython",
    "version": 3
   },
   "file_extension": ".py",
   "mimetype": "text/x-python",
   "name": "python",
   "nbconvert_exporter": "python",
   "pygments_lexer": "ipython3",
   "version": "3.7.6"
  }
 },
 "nbformat": 4,
 "nbformat_minor": 4
}
